<?xml version="1.0" ?>
<!-- =================================================================================== -->
<!-- |    This document was autogenerated by xacro from /home/bruno/catkin_ws/src/hex_bot/hex_bot_description/urdf/hex_bot.xacro | -->
<!-- |    EDITING THIS FILE BY HAND IS NOT RECOMMENDED                                 | -->
<!-- =================================================================================== -->
<!-- Main file for hexapod robot definition -->
<robot name="hex_bot" xmlns:xacro="http://ros.org/wiki/xacro">
  <material name="black">
    <color rgba="0.0 0.0 0.0 1.0"/>
  </material>
  <material name="blue">
    <color rgba="0.0 0.0 0.8 1.0"/>
  </material>
  <material name="green">
    <color rgba="0.0 0.8 0.0 1.0"/>
  </material>
  <material name="gray">
    <color rgba="0.2 0.2 0.2 1.0"/>
  </material>
  <material name="orange">
    <color rgba="1.0 0.423529411765 0.0392156862745 1.0"/>
  </material>
  <material name="brown">
    <color rgba="0.870588235294 0.811764705882 0.764705882353 1.0"/>
  </material>
  <material name="red">
    <color rgba="0.8 0.0 0.0 1.0"/>
  </material>
  <material name="white">
    <color rgba="1.0 1.0 1.0 1.0"/>
  </material>
  <gazebo>
    <plugin filename="libgazebo_ros_control.so" name="gazebo_ros_control">
      <robotNamespace>/hex_bot</robotNamespace>
    </plugin>
  </gazebo>
  <link name="base_link"/>
  <link name="body">
    <collision>
      <origin rpy="0 0 0" xyz="0 0 0"/>
      <geometry>
        <box size="0.15 0.1 0.05"/>
      </geometry>
    </collision>
    <visual>
      <origin rpy="0 0 0" xyz="0 0 0"/>
      <geometry>
        <box size="0.15 0.1 0.05"/>
      </geometry>
      <material name="white"/>
    </visual>
    <inertial>
      <mass value="0.5"/>
      <origin xyz="0 0 0"/>
      <inertia ixx="0.005" ixy="0.0" ixz="0.0" iyy="0.001" iyz="0.0" izz="0.001"/>
    </inertial>
  </link>
  <link name="LEG_servo_1">
    <collision>
      <origin rpy="0 0 0" xyz="-0.0125 0 0"/>
      <geometry>
        <box size="0.025 0.015 0.025"/>
      </geometry>
    </collision>
    <visual>
      <origin rpy="0 0 0" xyz="-0.0125 0 0"/>
      <geometry>
        <box size="0.025 0.015 0.025"/>
      </geometry>
      <material name="white"/>
    </visual>
    <inertial>
      <mass value="0.02"/>
      <origin rpy="0 0 0" xyz="-0.0125 0 0"/>
      <inertia ixx="0.0001" ixy="0.0" ixz="0.0" iyy="0.0001" iyz="0.0" izz="0.0001"/>
    </inertial>
  </link>
  <joint name="LEG_servo_1_to_body_joint" type="revolute">
    <parent link="body"/>
    <child link="LEG_servo_1"/>
    <origin rpy="0 0 -1.57" xyz="0.05 0.06 0"/>
    <axis xyz="0 0 1"/>
    <limit effort="3" lower="-1.57" upper="1.57" velocity="5"/>
  </joint>
  <link name="LEG_servo_2">
    <collision>
      <origin rpy="0 0 0" xyz="-0.0125 0 0"/>
      <geometry>
        <box size="0.025 0.015 0.025"/>
      </geometry>
    </collision>
    <visual>
      <origin rpy="0 0 0" xyz="-0.0125 0 0"/>
      <geometry>
        <box size="0.025 0.015 0.025"/>
      </geometry>
      <material name="white"/>
    </visual>
    <inertial>
      <mass value="0.02"/>
      <origin rpy="0 0 0" xyz="-0.0125 0 0"/>
      <inertia ixx="0.0001" ixy="0.0" ixz="0.0" iyy="0.0001" iyz="0.0" izz="0.0001"/>
    </inertial>
  </link>
  <joint name="LEG_servo_2_to_LEG_servo_1_joint" type="revolute">
    <parent link="LEG_servo_1"/>
    <child link="LEG_servo_2"/>
    <origin rpy="1.57 0 0" xyz="-0.025 0 0"/>
    <axis xyz="0 0 1"/>
    <limit effort="3" lower="-1.57" upper="1.57" velocity="5"/>
  </joint>
  <!-- Femur -->
  <link name="LEG_femur">
    <collision>
      <origin rpy="0 0 0" xyz="0 0 0"/>
      <geometry>
        <box size="0.07 0.01 0.015"/>
      </geometry>
    </collision>
    <visual>
      <origin rpy="0 0 0" xyz="0 0 0"/>
      <geometry>
        <box size="0.07 0.01 0.015"/>
      </geometry>
      <material name="white"/>
    </visual>
    <inertial>
      <mass value="0.15"/>
      <origin xyz="0 0 0"/>
      <inertia ixx="0.004" ixy="0.0" ixz="0.0" iyy="0.0006" iyz="0.0" izz="0.0006"/>
    </inertial>
  </link>
  <joint name="LEG_femur_to_LEG_servo_2_joint" type="fixed">
    <parent link="LEG_servo_2"/>
    <child link="LEG_femur"/>
    <origin rpy="0 0 0" xyz="-0.06 0 0"/>
  </joint>
  <!-- Servo 3 + Tibia -->
  <link name="LEG_servo_3">
    <collision>
      <origin rpy="0 0 0" xyz="-0.0125 0 0"/>
      <geometry>
        <box size="0.025 0.015 0.025"/>
      </geometry>
    </collision>
    <visual>
      <origin rpy="0 0 0" xyz="-0.0125 0 0"/>
      <geometry>
        <box size="0.025 0.015 0.025"/>
      </geometry>
      <material name="white"/>
    </visual>
    <inertial>
      <mass value="0.02"/>
      <origin rpy="0 0 0" xyz="-0.0125 0 0"/>
      <inertia ixx="0.0001" ixy="0.0" ixz="0.0" iyy="0.0001" iyz="0.0" izz="0.0001"/>
    </inertial>
  </link>
  <joint name="LEG_servo_3_to_LEG_femur_joint" type="revolute">
    <parent link="LEG_femur"/>
    <child link="LEG_servo_3"/>
    <origin rpy="0 0 1.57" xyz="-0.035 0 0"/>
    <axis xyz="0 0 1"/>
    <limit effort="3" lower="-1.57" upper="1.57" velocity="5"/>
  </joint>
  <link name="LEG_tibia">
    <collision>
      <origin rpy="0 0 0" xyz="0 0 0"/>
      <geometry>
        <box size="0.07 0.01 0.015"/>
      </geometry>
    </collision>
    <visual>
      <origin rpy="0 0 0" xyz="0 0 0"/>
      <geometry>
        <box size="0.07 0.01 0.015"/>
      </geometry>
      <material name="white"/>
    </visual>
    <inertial>
      <mass value="0.15"/>
      <origin xyz="0 0 0"/>
      <inertia ixx="0.004" ixy="0.0" ixz="0.0" iyy="0.0006" iyz="0.0" izz="0.0006"/>
    </inertial>
  </link>
  <joint name="LEG_tibia_to_LEG_servo_3_joint" type="fixed">
    <parent link="LEG_servo_3"/>
    <child link="LEG_tibia"/>
    <origin rpy="0 0 0" xyz="-0.06 0 0"/>
  </joint>
  <!-- Transmissions -->
  <transmission name="LEG_servo_1_to_body_joint_transmission">
    <type>transmission_interface/SimpleTransmission</type>
    <joint name="LEG_servo_1_to_body_joint">
      <hardwareInterface>EffortJointInterface</hardwareInterface>
    </joint>
    <actuator name="LEG_servo_1_to_body_joint_actuator">
      <hardwareInterface>EffortJointInterface</hardwareInterface>
      <mechanicalReduction>1</mechanicalReduction>
    </actuator>
  </transmission>
  <transmission name="LEG_servo_2_to_LEG_servo_1_joint_transmission">
    <type>transmission_interface/SimpleTransmission</type>
    <joint name="LEG_servo_2_to_LEG_servo_1_joint">
      <hardwareInterface>EffortJointInterface</hardwareInterface>
    </joint>
    <actuator name="LEG_servo_2_to_LEG_servo_1_joint_actuator">
      <hardwareInterface>EffortJointInterface</hardwareInterface>
      <mechanicalReduction>1</mechanicalReduction>
    </actuator>
  </transmission>
  <transmission name="LEG_servo_3_to_LEG_femur_joint_transmission">
    <type>transmission_interface/SimpleTransmission</type>
    <joint name="LEG_servo_3_to_LEG_femur_joint">
      <hardwareInterface>EffortJointInterface</hardwareInterface>
    </joint>
    <actuator name="LEG_servo_3_to_LEG_femur_joint_actuator">
      <hardwareInterface>EffortJointInterface</hardwareInterface>
      <mechanicalReduction>1</mechanicalReduction>
    </actuator>
  </transmission>
  <joint name="body_to_base_link_joint" type="fixed">
    <parent link="base_link"/>
    <child link="body"/>
  </joint>
</robot>
